Workbook

Sheet Dashboard
A1: Corrected HR Analytics Dashboard (Research & Development). Open the 'Interactive Dashboard' sheet to switch departments.

Sheet Interactive Dashboard
B1: HR ANALYTICS REPORT
B2: Workforce, terminations and salary | Faith Faithful Usenideh
B4: Department: | C4: Research & Development | F4: Employment: | G4: All | I4: Gender: | J4: Female | L4: Hire year: | M4: 1992
B6: Total Employees | E6: Current Employees | H6: Terminated | K6: Termination Rate | N6: Total Salary (USD) | Q6: Male (current) | T6: Female (current)
B7: =Analysis!$C$6 -> 0 | E7: =Analysis!$C$7 -> 0 | H7: =Analysis!$C$8 -> 0 | K7: =Analysis!$C$9 -> 0 | N7: =Analysis!$C$10 -> 0 | Q7: =Analysis!$C$11 -> 0 | T7: =Analysis!$C$12 -> 0

Sheet Sheet1
G10: ◄ FILTERS: click an orange box and pick from the drop-down; every card and chart updates

Sheet Analysis
B1: HR Analytics: calculations | E1: Employment type | F1: Gender | G1: Hire year from | H1: Hire year to
B2: Department shown (change it on the Dashboard) | C2: ='Interactive Dashboard'!$C$4 -> Research & Development | E2: ='Interactive Dashboard'!$G$4 -> All | F2: ='Interactive Dashboard'!$J$4 -> Female | G2: ='Interactive Dashboard'!$M$4 -> 1992
B3: Filter used in formulas | C3: =IF(C2="All departments","*",C2) -> Research & Development | E3: =IF(E2="All","*",E2) -> * | F3: =IF(F2="All","*",F2) -> Female | G3: =IF(G2="All years",1900,G2) -> 1992 | H3: =IF(G2="All years",2100,G2) -> 1992
B5: Key metrics
B6: Total employees (since inception) | C6: =COUNTIFS(Data!$E$2:$E$1471,Analysis!$C$3,Data!$AL$2:$AL$1471,Analysis!$E$3,Data!$H$2:$H$1471,Analysis!$F$3,Data!$AQ$2:$AQ$1471,">="&Analysis!$G$3,Data!$AQ$2:$AQ$1471,"<="&Analysis!$H$3) -> 0
B7: Current employees (headcount) | C7: =COUNTIFS(Data!$E$2:$E$1471,Analysis!$C$3,Data!$AL$2:$AL$1471,Analysis!$E$3,Data!$H$2:$H$1471,Analysis!$F$3,Data!$AQ$2:$AQ$1471,">="&Analysis!$G$3,Data!$AQ$2:$AQ$1471,"<="&Analysis!$H$3,Data!$C$2:$C$1471,"No") -> 0
B8: Terminated employees | C8: =COUNTIFS(Data!$E$2:$E$1471,Analysis!$C$3,Data!$AL$2:$AL$1471,Analysis!$E$3,Data!$H$2:$H$1471,Analysis!$F$3,Data!$AQ$2:$AQ$1471,">="&Analysis!$G$3,Data!$AQ$2:$AQ$1471,"<="&Analysis!$H$3,Data!$C$2:$C$1471,"Yes") -> 0
B9: Termination rate (terminated / headcount) | C9: =IFERROR(C8/C7,0) -> 0 | D9: Formula from the brief: Termination / Headcount
B10: Total salary, current employees (USD) | C10: =SUMIFS(Data!$Z$2:$Z$1471,Data!$E$2:$E$1471,Analysis!$C$3,Data!$AL$2:$AL$1471,Analysis!$E$3,Data!$H$2:$H$1471,Analysis!$F$3,Data!$AQ$2:$AQ$1471,">="&Analysis!$G$3,Data!$AQ$2:$AQ$1471,"<="&Analysis!$H$3,Data!$C$2:$C$1471,"No") -> 0
B11: Male (current) | C11: =COUNTIFS(Data!$E$2:$E$1471,Analysis!$C$3,Data!$AL$2:$AL$1471,Analysis!$E$3,Data!$H$2:$H$1471,Analysis!$F$3,Data!$AQ$2:$AQ$1471,">="&Analysis!$G$3,Data!$AQ$2:$AQ$1471,"<="&Analysis!$H$3,Data!$C$2:$C$1471,"No",Data!$H$2:$H$1471,"Male") -> 0
B12: Female (current) | C12: =COUNTIFS(Data!$E$2:$E$1471,Analysis!$C$3,Data!$AL$2:$AL$1471,Analysis!$E$3,Data!$H$2:$H$1471,Analysis!$F$3,Data!$AQ$2:$AQ$1471,">="&Analysis!$G$3,Data!$AQ$2:$AQ$1471,"<="&Analysis!$H$3,Data!$C$2:$C$1471,"No",Data!$H$2:$H$1471,"Female") -> 0
B14: Education level (current employees)
B15: Education | C15: Employees
B16: Doctor | C16: =COUNTIFS(Data!$E$2:$E$1471,Analysis!$C$3,Data!$AL$2:$AL$1471,Analysis!$E$3,Data!$H$2:$H$1471,Analysis!$F$3,Data!$AQ$2:$AQ$1471,">="&Analysis!$G$3,Data!$AQ$2:$AQ$1471,"<="&Analysis!$H$3,Data!$C$2:$C$1471,"No",Data!$F$2:$F$1471,"Doctor") -> 0
B17: Below College | C17: =COUNTIFS(Data!$E$2:$E$1471,Analysis!$C$3,Data!$AL$2:$AL$1471,Analysis!$E$3,Data!$H$2:$H$1471,Analysis!$F$3,Data!$AQ$2:$AQ$1471,">="&Analysis!$G$3,Data!$AQ$2:$AQ$1471,"<="&Analysis!$H$3,Data!$C$2:$C$1471,"No",Data!$F$2:$F$1471,"Below College") -> 0
B18: College | C18: =COUNTIFS(Data!$E$2:$E$1471,Analysis!$C$3,Data!$AL$2:$AL$1471,Analysis!$E$3,Data!$H$2:$H$1471,Analysis!$F$3,Data!$AQ$2:$AQ$1471,">="&Analysis!$G$3,Data!$AQ$2:$AQ$1471,"<="&Analysis!$H$3,Data!$C$2:$C$1471,"No",Data!$F$2:$F$1471,"College") -> 0
B19: Master | C19: =COUNTIFS(Data!$E$2:$E$1471,Analysis!$C$3,Data!$AL$2:$AL$1471,Analysis!$E$3,Data!$H$2:$H$1471,Analysis!$F$3,Data!$AQ$2:$AQ$1471,">="&Analysis!$G$3,Data!$AQ$2:$AQ$1471,"<="&Analysis!$H$3,Data!$C$2:$C$1471,"No",Data!$F$2:$F$1471,"Master") -> 0
B20: Bachelor | C20: =COUNTIFS(Data!$E$2:$E$1471,Analysis!$C$3,Data!$AL$2:$AL$1471,Analysis!$E$3,Data!$H$2:$H$1471,Analysis!$F$3,Data!$AQ$2:$AQ$1471,">="&Analysis!$G$3,Data!$AQ$2:$AQ$1471,"<="&Analysis!$H$3,Data!$C$2:$C$1471,"No",Data!$F$2:$F$1471,"Bachelor") -> 0
B22: Job satisfaction (current employees)
B23: Satisfaction | C23: Employees
B24: Low | C24: =COUNTIFS(Data!$E$2:$E$1471,Analysis!$C$3,Data!$AL$2:$AL$1471,Analysis!$E$3,Data!$H$2:$H$1471,Analysis!$F$3,Data!$AQ$2:$AQ$1471,">="&Analysis!$G$3,Data!$AQ$2:$AQ$1471,"<="&Analysis!$H$3,Data!$C$2:$C$1471,"No",Data!$K$2:$K$1471,"Low") -> 0
B25: Medium | C25: =COUNTIFS(Data!$E$2:$E$1471,Analysis!$C$3,Data!$AL$2:$AL$1471,Analysis!$E$3,Data!$H$2:$H$1471,Analysis!$F$3,Data!$AQ$2:$AQ$1471,">="&Analysis!$G$3,Data!$AQ$2:$AQ$1471,"<="&Analysis!$H$3,Data!$C$2:$C$1471,"No",Data!$K$2:$K$1471,"Medium") -> 0
B26: High | C26: =COUNTIFS(Data!$E$2:$E$1471,Analysis!$C$3,Data!$AL$2:$AL$1471,Analysis!$E$3,Data!$H$2:$H$1471,Analysis!$F$3,Data!$AQ$2:$AQ$1471,">="&Analysis!$G$3,Data!$AQ$2:$AQ$1471,"<="&Analysis!$H$3,Data!$C$2:$C$1471,"No",Data!$K$2:$K$1471,"High") -> 0
B27: Very High | C27: =COUNTIFS(Data!$E$2:$E$1471,Analysis!$C$3,Data!$AL$2:$AL$1471,Analysis!$E$3,Data!$H$2:$H$1471,Analysis!$F$3,Data!$AQ$2:$AQ$1471,">="&Analysis!$G$3,Data!$AQ$2:$AQ$1471,"<="&Analysis!$H$3,Data!$C$2:$C$1471,"No",Data!$K$2:$K$1471,"Very High") -> 0
B29: Work-life balance (current employees)
B30: Work-life balance | C30: Employees
B31: Bad | C31: =COUNTIFS(Data!$E$2:$E$1471,Analysis!$C$3,Data!$AL$2:$AL$1471,Analysis!$E$3,Data!$H$2:$H$1471,Analysis!$F$3,Data!$AQ$2:$AQ$1471,">="&Analysis!$G$3,Data!$AQ$2:$AQ$1471,"<="&Analysis!$H$3,Data!$C$2:$C$1471,"No",Data!$M$2:$M$1471,"Bad") -> 0
B32: Good | C32: =COUNTIFS(Data!$E$2:$E$1471,Analysis!$C$3,Data!$AL$2:$AL$1471,Analysis!$E$3,Data!$H$2:$H$1471,Analysis!$F$3,Data!$AQ$2:$AQ$1471,">="&Analysis!$G$3,Data!$AQ$2:$AQ$1471,"<="&Analysis!$H$3,Data!$C$2:$C$1471,"No",Data!$M$2:$M$1471,"Good") -> 0
B33: Better | C33: =COUNTIFS(Data!$E$2:$E$1471,Analysis!$C$3,Data!$AL$2:$AL$1471,Analysis!$E$3,Data!$H$2:$H$1471,Analysis!$F$3,Data!$AQ$2:$AQ$1471,">="&Analysis!$G$3,Data!$AQ$2:$AQ$1471,"<="&Analysis!$H$3,Data!$C$2:$C$1471,"No",Data!$M$2:$M$1471,"Better") -> 0
B34: Best | C34: =COUNTIFS(Data!$E$2:$E$1471,Analysis!$C$3,Data!$AL$2:$AL$1471,Analysis!$E$3,Data!$H$2:$H$1471,Analysis!$F$3,Data!$AQ$2:$AQ$1471,">="&Analysis!$G$3,Data!$AQ$2:$AQ$1471,"<="&Analysis!$H$3,Data!$C$2:$C$1471,"No",Data!$M$2:$M$1471,"Best") -> 0
B36: Quarterly hires and terminations
B37: Quarter | C37: New hires | D37: Terminations | E37: Hires use DateStart (all hires); terminations use DateDeparture
B38: Qtr1 | C38: =COUNTIFS(Data!$E$2:$E$1471,Analysis!$C$3,Data!$AL$2:$AL$1471,Analysis!$E$3,Data!$H$2:$H$1471,Analysis!$F$3,Data!$AQ$2:$AQ$1471,">="&Analysis!$G$3,Data!$AQ$2:$AQ$1471,"<="&Analysis!$H$3,Data!$AM$2:$AM$1471,1) -> 0 | D38: =COUNTIFS(Data!$E$2:$E$1471,Analysis!$C$3,Data!$AL$2:$AL$1471,Analysis!$E$3,Data!$H$2:$H$1471,Analysis!$F$3,Data!$AQ$2:$AQ$1471,">="&Analysis!$G$3,Data!$AQ$2:$AQ$1471,"<="&Analysis!$H$3,Data!$AO$2:$AO$1471,1) -> 0
B39: Qtr2 | C39: =COUNTIFS(Data!$E$2:$E$1471,Analysis!$C$3,Data!$AL$2:$AL$1471,Analysis!$E$3,Data!$H$2:$H$1471,Analysis!$F$3,Data!$AQ$2:$AQ$1471,">="&Analysis!$G$3,Data!$AQ$2:$AQ$1471,"<="&Analysis!$H$3,Data!$AM$2:$AM$1471,2) -> 0 | D39: =COUNTIFS(Data!$E$2:$E$1471,Analysis!$C$3,Data!$AL$2:$AL$1471,Analysis!$E$3,Data!$H$2:$H$1471,Analysis!$F$3,Data!$AQ$2:$AQ$1471,">="&Analysis!$G$3,Data!$AQ$2:$AQ$1471,"<="&Analysis!$H$3,Data!$AO$2:$AO$1471,2) -> 0
B40: Qtr3 | C40: =COUNTIFS(Data!$E$2:$E$1471,Analysis!$C$3,Data!$AL$2:$AL$1471,Analysis!$E$3,Data!$H$2:$H$1471,Analysis!$F$3,Data!$AQ$2:$AQ$1471,">="&Analysis!$G$3,Data!$AQ$2:$AQ$1471,"<="&Analysis!$H$3,Data!$AM$2:$AM$1471,3) -> 0 | D40: =COUNTIFS(Data!$E$2:$E$1471,Analysis!$C$3,Data!$AL$2:$AL$1471,Analysis!$E$3,Data!$H$2:$H$1471,Analysis!$F$3,Data!$AQ$2:$AQ$1471,">="&Analysis!$G$3,Data!$AQ$2:$AQ$1471,"<="&Analysis!$H$3,Data!$AO$2:$AO$1471,3) -> 0
B41: Qtr4 | C41: =COUNTIFS(Data!$E$2:$E$1471,Analysis!$C$3,Data!$AL$2:$AL$1471,Analysis!$E$3,Data!$H$2:$H$1471,Analysis!$F$3,Data!$AQ$2:$AQ$1471,">="&Analysis!$G$3,Data!$AQ$2:$AQ$1471,"<="&Analysis!$H$3,Data!$AM$2:$AM$1471,4) -> 0 | D41: =COUNTIFS(Data!$E$2:$E$1471,Analysis!$C$3,Data!$AL$2:$AL$1471,Analysis!$E$3,Data!$H$2:$H$1471,Analysis!$F$3,Data!$AQ$2:$AQ$1471,">="&Analysis!$G$3,Data!$AQ$2:$AQ$1471,"<="&Analysis!$H$3,Data!$AO$2:$AO$1471,4) -> 0
B43: Monthly terminations (by leaving month) and salary (by hire month)
B44: Month | C44: Terminations | D44: Salary of current staff hired
B45: Jan | C45: =COUNTIFS(Data!$E$2:$E$1471,Analysis!$C$3,Data!$AL$2:$AL$1471,Analysis!$E$3,Data!$H$2:$H$1471,Analysis!$F$3,Data!$AQ$2:$AQ$1471,">="&Analysis!$G$3,Data!$AQ$2:$AQ$1471,"<="&Analysis!$H$3,Data!$AP$2:$AP$1471,1) -> 0 | D45: =SUMIFS(Data!$Z$2:$Z$1471,Data!$E$2:$E$1471,Analysis!$C$3,Data!$AL$2:$AL$1471,Analysis!$E$3,Data!$H$2:$H$1471,Analysis!$F$3,Data!$AQ$2:$AQ$1471,">="&Analysis!$G$3,Data!$AQ$2:$AQ$1471,"<="&Analysis!$H$3,Data!$C$2:$C$1471,"No",Data!$AN$2:$AN$1471,1) -> 0
B46: Feb | C46: =COUNTIFS(Data!$E$2:$E$1471,Analysis!$C$3,Data!$AL$2:$AL$1471,Analysis!$E$3,Data!$H$2:$H$1471,Analysis!$F$3,Data!$AQ$2:$AQ$1471,">="&Analysis!$G$3,Data!$AQ$2:$AQ$1471,"<="&Analysis!$H$3,Data!$AP$2:$AP$1471,2) -> 0 | D46: =SUMIFS(Data!$Z$2:$Z$1471,Data!$E$2:$E$1471,Analysis!$C$3,Data!$AL$2:$AL$1471,Analysis!$E$3,Data!$H$2:$H$1471,Analysis!$F$3,Data!$AQ$2:$AQ$1471,">="&Analysis!$G$3,Data!$AQ$2:$AQ$1471,"<="&Analysis!$H$3,Data!$C$2:$C$1471,"No",Data!$AN$2:$AN$1471,2) -> 0
...

Sheet Data
A1: ID_employe | B1: Age | C1: Attrition | D1: BusinessTravel | E1: Department | F1: Education | G1: EnvironmentSatisfaction | H1: Gender | I1: JobInvolvement | J1: Job Role | K1: JobSatisfaction | L1: PerformanceRating | M1: WorkLifeBalance | N1: MaritalStatus | O1: StockOption | P1: OverTime | Q1: PercentSalaryHike | R1: NumCompaniesWorked | S1: TotalWorkingYears | T1: YearsSinceLastPromotion | U1: YearsWithCurrManager | V1: DistanceFromHome | W1: HourlyRate | X1: DailyRate | Y1: MonthlyRate | Z1: Salary | AA1: TrainingTimesLastYear | AB1: DateToday | AC1: DateBirth | AD1: DateStart | AE1: DateDeparture | AF1: YearsAtCompany | AG1: AgeGroup | AH1: TerminationType | AI1: AgeHire | AJ1: HireType | AK1: YearsAtCompany Group | AL1: EmploymentType | AM1: HireQuarter | AN1: HireMonth | AO1: LeaveQuarter | AP1: LeaveMonth | AQ1: HireYear
A2: 1522 | B2: 37 | C2: Yes | D2: Travel_Rarely | E2: Research & Development | F2: Master | G2: Low | H2: Male | I2: Medium | J2: Research Scientist | K2: Low | L2: Excellent | M2: Bad | N2: Single | P2: No | Q2: 13 | R2: 6 | S2: 11 | T2: 0 | U2: 7 | V2: 1 | W2: 100 | X2: 224 | Y2: 7568 | Z2: 2362 | AA2: 2 | AB2: 44773 | AC2: 30826 | AD2: 37136 | AE2: 40205 | AF2: 8 | AG2: 3_Between 30 and 40 | AH2: 1 | AI2: 29 | AJ2: 1 | AK2: 4_Between 5-10 years | AL2: Full-time | AM2: =ROUNDUP(MONTH(AD2)/3,0) -> 3 | AN2: =MONTH(AD2) -> 9 | AO2: =IF(C2="Yes",ROUNDUP(MONTH(AE2)/3,0),"") -> 1 | AP2: =IF(C2="Yes",MONTH(AE2),"") -> 1 | AQ2: =YEAR(AD2) -> 2001
A3: 1101 | B3: 42 | C3: Yes | D3: Travel_Frequently | E3: Research & Development | F3: Master | G3: Low | H3: Female | I3: Medium | J3: Research Scientist | K3: High | L3: Outstanding | M3: Better | N3: Single | P3: No | Q3: 22 | R3: 1 | S3: 14 | T3: 3 | U3: 8 | V3: 29 | W3: 54 | X3: 827 | Y3: 3129 | Z3: 4508 | AA3: 4 | AB3: 44773 | AC3: 29226 | AD3: 35808 | AE3: 40294 | AF3: 12 | AG3: 4_Between 40 and 50 | AH3: 1 | AI3: 30 | AJ3: 1 | AK3: 5_Between 10-15 years | AL3: Full-time | AM3: =ROUNDUP(MONTH(AD3)/3,0) -> 1 | AN3: =MONTH(AD3) -> 1 | AO3: =IF(C3="Yes",ROUNDUP(MONTH(AE3)/3,0),"") -> 2 | AP3: =IF(C3="Yes",MONTH(AE3),"") -> 4 | AQ3: =YEAR(AD3) -> 1998
A4: 1299 | B4: 29 | C4: Yes | D4: Travel_Rarely | E4: Research & Development | F4: Bachelor | G4: Medium | H4: Female | I4: High | J4: Laboratory Technician | K4: High | L4: Excellent | M4: Better | N4: Divorced | O4: Mid | P4: Yes | Q4: 13 | R4: 3 | S4: 10 | T4: 7 | U4: 7 | V4: 7 | W4: 39 | X4: 806 | Y4: 17285 | Z4: 3339 | AA4: 2 | AB4: 44773 | AC4: 34281 | AD4: 39917 | AE4: 42304 | AF4: 7 | AG4: 2_Between 20 and 30 | AH4: 2 | AI4: 22 | AJ4: 1 | AK4: 4_Between 5-10 years | AL4: Contractor | AM4: =ROUNDUP(MONTH(AD4)/3,0) -> 2 | AN4: =MONTH(AD4) -> 4 | AO4: =IF(C4="Yes",ROUNDUP(MONTH(AE4)/3,0),"") -> 4 | AP4: =IF(C4="Yes",MONTH(AE4),"") -> 10 | AQ4: =YEAR(AD4) -> 2009
A5: 1457 | B5: 46 | C5: Yes | D5: Travel_Rarely | E5: Sales | F5: Bachelor | G5: Low | H5: Male | I5: High | J5: Sales Executive | K5: Very High | L5: Good | M5: Best | N5: Divorced | O5: Low | P5: No | Q5: 11 | R5: 4 | S5: 28 | T5: 4 | U5: 3 | V5: 9 | W5: 52 | X5: 377 | Y5: 15986 | Z5: 10096 | AA5: 1 | AB5: 44773 | AC5: 28009 | AD5: 40018 | AE5: 42487 | AF5: 7 | AG5: 4_Between 40 and 50 | AH5: 1 | AI5: 39 | AJ5: 1 | AK5: 4_Between 5-10 years | AL5: Full-time | AM5: =ROUNDUP(MONTH(AD5)/3,0) -> 3 | AN5: =MONTH(AD5) -> 7 | AO5: =IF(C5="Yes",ROUNDUP(MONTH(AE5)/3,0),"") -> 2 | AP5: =IF(C5="Yes",MONTH(AE5),"") -> 4 | AQ5: =YEAR(AD5) -> 2009
A6: 1807 | B6: 34 | C6: Yes | D6: Travel_Frequently | E6: Research & Development | F6: Master | G6: Very High | H6: Male | I6: High | J6: Laboratory Technician | K6: Low | L6: Low | M6: Good | N6: Married | O6: Low | P6: No | Q6: 17 | R6: 4 | S6: 11 | T6: 0 | U6: 6 | V6: 9 | W6: 93 | X6: 234 | Y6: 6208 | Z6: 5346 | AA6: 3 | AB6: 44773 | AC6: 32374 | AD6: 40283 | AE6: 42505 | AF6: 6 | AG6: 3_Between 30 and 40 | AH6: 2 | AI6: 28 | AJ6: 1 | AK6: 4_Between 5-10 years | AL6: Full-time | AM6: =ROUNDUP(MONTH(AD6)/3,0) -> 2 | AN6: =MONTH(AD6) -> 4 | AO6: =IF(C6="Yes",ROUNDUP(MONTH(AE6)/3,0),"") -> 2 | AP6: =IF(C6="Yes",MONTH(AE6),"") -> 5 | AQ6: =YEAR(AD6) -> 2010
A7: 299 | B7: 30 | C7: Yes | D7: Travel_Frequently | E7: Sales | F7: Master | G7: High | H7: Female | I7: Medium | J7: Sales Executive | K7: Low | L7: Excellent | M7: Good | N7: Single | P7: No | Q7: 15 | R7: 5 | S7: 9 | T7: 0 | U7: 1 | V7: 26 | W7: 52 | X7: 334 | Y7: 22967 | Z7: 6696 | AA7: 5 | AB7: 44773 | AC7: 33857 | AD7: 40598 | AE7: 42698 | AF7: 6 | AG7: 3_Between 30 and 40 | AH7: 2 | AI7: 24 | AJ7: 1 | AK7: 4_Between 5-10 years | AL7: Full-time | AM7: =ROUNDUP(MONTH(AD7)/3,0) -> 1 | AN7: =MONTH(AD7) -> 2 | AO7: =IF(C7="Yes",ROUNDUP(MONTH(AE7)/3,0),"") -> 4 | AP7: =IF(C7="Yes",MONTH(AE7),"") -> 11 | AQ7: =YEAR(AD7) -> 2011
A8: 300 | B8: 29 | C8: Yes | D8: Travel_Rarely | E8: Research & Development | F8: Bachelor | G8: High | H8: Male | I8: High | J8: Research Scientist | K8: High | L8: Excellent | M8: Good | N8: Single | P8: No | Q8: 14 | R8: 0 | S8: 7 | T8: 1 | U8: 5 | V8: 1 | W8: 85 | X8: 992 | Y8: 19757 | Z8: 2058 | AA8: 1 | AB8: 44773 | AC8: 34527 | AD8: 40588 | AE8: 42712 | AF8: 6 | AG8: 2_Between 20 and 30 | AH8: 1 | AI8: 23 | AJ8: 1 | AK8: 4_Between 5-10 years | AL8: Full-time | AM8: =ROUNDUP(MONTH(AD8)/3,0) -> 1 | AN8: =MONTH(AD8) -> 2 | AO8: =IF(C8="Yes",ROUNDUP(MONTH(AE8)/3,0),"") -> 4 | AP8: =IF(C8="Yes",MONTH(AE8),"") -> 12 | AQ8: =YEAR(AD8) -> 2011
A9: 1200 | B9: 44 | C9: Yes | D9: Travel_Rarely | E9: Research & Development | F9: Master | G9: High | H9: Male | I9: High | J9: Research Scientist | K9: High | L9: Low | M9: Better | N9: Single | P9: Yes | Q9: 11 | R9: 1 | S9: 6 | T9: 0 | U9: 2 | V9: 10 | W9: 96 | X9: 1097 | Y9: 10826 | Z9: 2936 | AA9: 4 | AB9: 44773 | AC9: 28761 | AD9: 40710 | AE9: 42730 | AF9: 6 | AG9: 4_Between 40 and 50 | AH9: 1 | AI9: 38 | AJ9: 1 | AK9: 4_Between 5-10 years | AL9: Full-time | AM9: =ROUNDUP(MONTH(AD9)/3,0) -> 2 | AN9: =MONTH(AD9) -> 6 | AO9: =IF(C9="Yes",ROUNDUP(MONTH(AE9)/3,0),"") -> 4 | AP9: =IF(C9="Yes",MONTH(AE9),"") -> 12 | AQ9: =YEAR(AD9) -> 2011
A10: 1295 | B10: 44 | C10: Yes | D10: Travel_Rarely | E10: Research & Development | F10: Bachelor | G10: Low | H10: Female | I10: High | J10: Healthcare Representative | K10: Very High | L10: Good | M10: Better | N10: Married | O10: Low | P10: No | Q10: 11 | R10: 1 | S10: 10 | T10: 0 | U10: 5 | V10: 15 | W10: 73 | X10: 621 | Y10: 14075 | Z10: 7978 | AA10: 2 | AB10: 44773 | AC10: 28757 | AD10: 39422 | AE10: 42737 | AF10: 9 | AG10: 4_Between 40 and 50 | AH10: 1 | AI10: 35 | AJ10: 1 | AK10: 4_Between 5-10 years | AL10: Full-time | AM10: =ROUNDUP(MONTH(AD10)/3,0) -> 4 | AN10: =MONTH(AD10) -> 12 | AO10: =IF(C10="Yes",ROUNDUP(MONTH(AE10)/3,0),"") -> 1 | AP10: =IF(C10="Yes",MONTH(AE10),"") -> 1 | AQ10: =YEAR(AD10) -> 2007
A11: 647 | B11: 33 | C11: Yes | D11: Travel_Frequently | E11: Research & Development | F11: Bachelor | G11: Low | H11: Female | I11: High | J11: Laboratory Technician | K11: High | L11: Excellent | M11: Better | N11: Married | O11: Low | P11: Yes | Q11: 16 | R11: 1 | S11: 6 | T11: 1 | U11: 2 | V11: 7 | W11: 55 | X11: 1287 | Y11: 14168 | Z11: 2886 | AA11: 4 | AB11: 44773 | AC11: 32424 | AD11: 40872 | AE11: 42760 | AF11: 5 | AG11: 3_Between 30 and 40 | AH11: 1 | AI11: 28 | AJ11: 1 | AK11: 3_Between 3-5 years | AL11: Full-time | AM11: =ROUNDUP(MONTH(AD11)/3,0) -> 4 | AN11: =MONTH(AD11) -> 11 | AO11: =IF(C11="Yes",ROUNDUP(MONTH(AE11)/3,0),"") -> 1 | AP11: =IF(C11="Yes",MONTH(AE11),"") -> 1 | AQ11: =YEAR(AD11) -> 2011
A12: 401 | B12: 35 | C12: Yes | D12: Travel_Rarely | E12: Sales | F12: Master | G12: Very High | H12: Male | I12: Medium | J12: Sales Executive | K12: Very High | L12: Excellent | M12: Better | N12: Single | P12: Yes | Q12: 12 | R12: 1 | S12: 8 | T12: 7 | U12: 4 | V12: 4 | W12: 48 | X12: 950 | Y12: 8450 | Z12: 5828 | AA12: 0 | AB12: 44773 | AC12: 31859 | AD12: 40219 | AE12: 42787 | AF12: 7 | AG12: 3_Between 30 and 40 | AH12: 1 | AI12: 28 | AJ12: 1 | AK12: 4_Between 5-10 years | AL12: Full-time | AM12: =ROUNDUP(MONTH(AD12)/3,0) -> 1 | AN12: =MONTH(AD12) -> 2 | AO12: =IF(C12="Yes",ROUNDUP(MONTH(AE12)/3,0),"") -> 1 | AP12: =IF(C12="Yes",MONTH(AE12),"") -> 2 | AQ12: =YEAR(AD12) -> 2010
A13: 190 | B13: 32 | C13: Yes | D13: Travel_Rarely | E13: Research & Development | F13: Bachelor | G13: Low | H13: Female | I13: High | J13: Laboratory Technician | K13: Low | L13: Good | M13: Best | N13: Single | P13: No | Q13: 22 | R13: 7 | S13: 10 | T13: 0 | U13: 4 | V13: 9 | W13: 41 | X13: 1033 | Y13: 10224 | Z13: 4200 | AA13: 2 | AB13: 44773 | AC13: 33133 | AD13: 41302 | AE13: 42944 | AF13: 4 | AG13: 3_Between 30 and 40 | AH13: 2 | AI13: 28 | AJ13: 1 | AK13: 3_Between 3-5 years | AL13: Full-time | AM13: =ROUNDUP(MONTH(AD13)/3,0) -> 1 | AN13: =MONTH(AD13) -> 1 | AO13: =IF(C13="Yes",ROUNDUP(MONTH(AE13)/3,0),"") -> 3 | AP13: =IF(C13="Yes",MONTH(AE13),"") -> 7 | AQ13: =YEAR(AD13) -> 2013
A14: 325 | B14: 33 | C14: Yes | D14: Travel_Rarely | E14: Research & Development | F14: Bachelor | G14: High | H14: Male | I14: High | J14: Laboratory Technician | K14: Very High | L14: Excellent | M14: Bad | N14: Married | O14: Low | P14: Yes | Q14: 13 | R14: 5 | S14: 8 | T14: 0 | U14: 4 | V14: 14 | W14: 58 | X14: 813 | Y14: 22149 | Z14: 2436 | AA14: 2 | AB14: 44773 | AC14: 32876 | AD14: 41472 | AE14: 42958 | AF14: 4 | AG14: 3_Between 30 and 40 | AH14: 1 | AI14: 29 | AJ14: 1 | AK14: 3_Between 3-5 years | AL14: Contractor | AM14: =ROUNDUP(MONTH(AD14)/3,0) -> 3 | AN14: =MONTH(AD14) -> 7 | AO14: =IF(C14="Yes",ROUNDUP(MONTH(AE14)/3,0),"") -> 3 | AP14: =IF(C14="Yes",MONTH(AE14),"") -> 8 | AQ14: =YEAR(AD14) -> 2013
A15: 1310 | B15: 39 | C15: Yes | D15: Travel_Rarely | E15: Research & Development | F15: Bachelor | G15: High | H15: Male | I15: High | J15: Research Scientist | K15: Low | L15: Excellent | M15: Better | N15: Single | P15: No | Q15: 13 | R15: 0 | S15: 6 | T15: 0 | U15: 3 | V15: 23 | W15: 93 | X15: 360 | Y15: 22154 | Z15: 3904 | AA15: 2 | AB15: 44773 | AC15: 30731 | AD15: 41393 | AE15: 42962 | AF15: 4 | AG15: 3_Between 30 and 40 | AH15: 1 | AI15: 35 | AJ15: 1 | AK15: 3_Between 3-5 years | AL15: Full-time | AM15: =ROUNDUP(MONTH(AD15)/3,0) -> 2 | AN15: =MONTH(AD15) -> 4 | AO15: =IF(C15="Yes",ROUNDUP(MONTH(AE15)/3,0),"") -> 3 | AP15: =IF(C15="Yes",MONTH(AE15),"") -> 8 | AQ15: =YEAR(AD15) -> 2013
A16: 1004 | B16: 30 | C16: Yes | D16: Travel_Rarely | E16: Research & Development | F16: Bachelor | G16: Low | H16: Female | I16: High | J16: Research Scientist | K16: High | L16: Excellent | M16: Better | N16: Married | P16: Yes | Q16: 11 | R16: 4 | S16: 7 | T16: 0 | U16: 1 | V16: 22 | W16: 48 | X16: 138 | Y16: 11539 | Z16: 2132 | AA16: 2 | AB16: 44773 | AC16: 34168 | AD16: 41367 | AE16: 42967 | AF16: 4 | AG16: 3_Between 30 and 40 | AH16: 1 | AI16: 26 | AJ16: 1 | AK16: 3_Between 3-5 years | AL16: Full-time | AM16: =ROUNDUP(MONTH(AD16)/3,0) -> 2 | AN16: =MONTH(AD16) -> 4 | AO16: =IF(C16="Yes",ROUNDUP(MONTH(AE16)/3,0),"") -> 3 | AP16: =IF(C16="Yes",MONTH(AE16),"") -> 8 | AQ16: =YEAR(AD16) -> 2013
A17: 147 | B17: 34 | C17: Yes | D17: Travel_Frequently | E17: Research & Development | F17: Bachelor | G17: Low | H17: Male | I17: Low | J17: Laboratory Technician | K17: High | L17: Outstanding | M17: Better | N17: Single | P17: Yes | Q17: 24 | R17: 1 | S17: 9 | T17: 0 | U17: 6 | V17: 7 | W17: 66 | X17: 658 | Y17: 22887 | Z17: 6074 | AA17: 3 | AB17: 44773 | AC17: 32474 | AD17: 40033 | AE17: 42968 | AF17: 8 | AG17: 3_Between 30 and 40 | AH17: 2 | AI17: 26 | AJ17: 1 | AK17: 4_Between 5-10 years | AL17: Full-time | AM17: =ROUNDUP(MONTH(AD17)/3,0) -> 3 | AN17: =MONTH(AD17) -> 8 | AO17: =IF(C17="Yes",ROUNDUP(MONTH(AE17)/3,0),"") -> 3 | AP17: =IF(C17="Yes",MONTH(AE17),"") -> 8 | AQ17: =YEAR(AD17) -> 2009
A18: 1042 | B18: 36 | C18: Yes | D18: Travel_Rarely | E18: Research & Development | F18: Master | G18: High | H18: Female | I18: Very High | J18: Laboratory Technician | K18: Low | L18: Excellent | M18: Better | N18: Single | P18: No | Q18: 16 | R18: 1 | S18: 18 | T18: 15 | U18: 14 | V18: 16 | W18: 43 | X18: 885 | Y18: 8269 | Z18: 2743 | AA18: 1 | AB18: 44773 | AC18: 31893 | AD18: 36863 | AE18: 42987 | AF18: 17 | AG18: 3_Between 30 and 40 | AH18: 1 | AI18: 19 | AJ18: 1 | AK18: 7_15+ years | AL18: Full-time | AM18: =ROUNDUP(MONTH(AD18)/3,0) -> 4 | AN18: =MONTH(AD18) -> 12 | AO18: =IF(C18="Yes",ROUNDUP(MONTH(AE18)/3,0),"") -> 3 | AP18: =IF(C18="Yes",MONTH(AE18),"") -> 9 | AQ18: =YEAR(AD18) -> 2000
A19: 502 | B19: 34 | C19: Yes | D19: Non-Travel | E19: Sales | F19: Bachelor | G19: Low | H19: Male | I19: Very High | J19: Sales Executive | K19: Very High | L19: Excellent | M19: Good | N19: Single | P19: Yes | Q19: 13 | R19: 8 | S19: 9 | T19: 0 | U19: 4 | V19: 19 | W19: 67 | X19: 1362 | Y19: 4652 | Z19: 5304 | AA19: 3 | AB19: 44773 | AC19: 32391 | AD19: 41437 | AE19: 43000 | AF19: 4 | AG19: 3_Between 30 and 40 | AH19: 1 | AI19: 30 | AJ19: 1 | AK19: 3_Between 3-5 years | AL19: Full-time | AM19: =ROUNDUP(MONTH(AD19)/3,0) -> 2 | AN19: =MONTH(AD19) -> 6 | AO19: =IF(C19="Yes",ROUNDUP(MONTH(AE19)/3,0),"") -> 3 | AP19: =IF(C19="Yes",MONTH(AE19),"") -> 9 | AQ19: =YEAR(AD19) -> 2013
A20: 967 | B20: 36 | C20: Yes | D20: Travel_Rarely | E20: Sales | F20: Below College | G20: High | H20: Male | I20: Medium | J20: Sales Executive | K20: Very High | L20: Excellent | M20: Better | N20: Married | O20: Low | P20: Yes | Q20: 11 | R20: 1 | S20: 16 | T20: 3 | U20: 7 | V20: 3 | W20: 51 | X20: 530 | Y20: 5518 | Z20: 10325 | AA20: 6 | AB20: 44773 | AC20: 31912 | AD20: 37376 | AE20: 43001 | AF20: 15 | AG20: 3_Between 30 and 40 | AH20: 1 | AI20: 21 | AJ20: 1 | AK20: 7_15+ years | AL20: Contractor | AM20: =ROUNDUP(MONTH(AD20)/3,0) -> 2 | AN20: =MONTH(AD20) -> 4 | AO20: =IF(C20="Yes",ROUNDUP(MONTH(AE20)/3,0),"") -> 3 | AP20: =IF(C20="Yes",MONTH(AE20),"") -> 9 | AQ20: =YEAR(AD20) -> 2002
A21: 1157 | B21: 33 | C21: Yes | D21: Travel_Rarely | E21: Sales | F21: Master | G21: Low | H21: Female | I21: High | J21: Sales Executive | K21: Low | L21: Good | M21: Better | N21: Single | P21: Yes | Q21: 17 | R21: 0 | S21: 6 | T21: 0 | U21: 3 | V21: 9 | W21: 77 | X21: 603 | Y21: 18385 | Z21: 8224 | AA21: 3 | AB21: 44773 | AC21: 33003 | AD21: 41331 | AE21: 43019 | AF21: 5 | AG21: 3_Between 30 and 40 | AH21: 1 | AI21: 28 | AJ21: 1 | AK21: 3_Between 3-5 years | AL21: Full-time | AM21: =ROUNDUP(MONTH(AD21)/3,0) -> 1 | AN21: =MONTH(AD21) -> 2 | AO21: =IF(C21="Yes",ROUNDUP(MONTH(AE21)/3,0),"") -> 4 | AP21: =IF(C21="Yes",MONTH(AE21),"") -> 10 | AQ21: =YEAR(AD21) -> 2013
A22: 1573 | B22: 38 | C22: Yes | D22: Travel_Rarely | E22: Research & Development | F22: Bachelor | G22: High | H22: Male | I22: High | J22: Manufacturing Director | K22: Medium | L22: Good | M22: Better | N22: Married | O22: Mid | P22: No | Q22: 11 | R22: 4 | S22: 7 | T22: 1 | U22: 4 | V22: 2 | W22: 81 | X22: 903 | Y22: 7653 | Z22: 4855 | AA22: 2 | AB22: 44773 | AC22: 30949 | AD22: 41469 | AE22: 43036 | AF22: 4 | AG22: 3_Between 30 and 40 | AH22: 2 | AI22: 34 | AJ22: 1 | AK22: 3_Between 3-5 years | AL22: Full-time | AM22: =ROUNDUP(MONTH(AD22)/3,0) -> 3 | AN22: =MONTH(AD22) -> 7 | AO22: =IF(C22="Yes",ROUNDUP(MONTH(AE22)/3,0),"") -> 4 | AP22: =IF(C22="Yes",MONTH(AE22),"") -> 10 | AQ22: =YEAR(AD22) -> 2013
A23: 554 | B23: 24 | C23: Yes | D23: Travel_Rarely | E23: Sales | F23: Below College | G23: Low | H23: Female | I23: High | J23: Sales Representative | K23: Medium | L23: Excellent | M23: Better | N23: Single | P23: Yes | Q23: 16 | R23: 1 | S23: 6 | T23: 1 | U23: 4 | V23: 1 | W23: 62 | X23: 1448 | Y23: 21972 | Z23: 3202 | AA23: 4 | AB23: 44773 | AC23: 36193 | AD23: 41493 | AE23: 43047 | AF23: 4 | AG23: 2_Between 20 and 30 | AH23: 1 | AI23: 20 | AJ23: 1 | AK23: 3_Between 3-5 years | AL23: Full-time | AM23: =ROUNDUP(MONTH(AD23)/3,0) -> 3 | AN23: =MONTH(AD23) -> 8 | AO23: =IF(C23="Yes",ROUNDUP(MONTH(AE23)/3,0),"") -> 4 | AP23: =IF(C23="Yes",MONTH(AE23),"") -> 11 | AQ23: =YEAR(AD23) -> 2013
A24: 161 | B24: 56 | C24: Yes | D24: Travel_Rarely | E24: Research & Development | F24: Master | G24: Medium | H24: Female | I24: High | J24: Research Scientist | K24: Medium | L24: Excellent | M24: Better | N24: Married | O24: High | P24: Yes | Q24: 18 | R24: 9 | S24: 7 | T24: 4 | U24: 3 | V24: 14 | W24: 72 | X24: 441 | Y24: 4510 | Z24: 4963 | AA24: 2 | AB24: 44773 | AC24: 24365 | AD24: 41476 | AE24: 43049 | AF24: 4 | AG24: 5_Between 50 and 60 | AH24: 1 | AI24: 52 | AJ24: 1 | AK24: 3_Between 3-5 years | AL24: Full-time | AM24: =ROUNDUP(MONTH(AD24)/3,0) -> 3 | AN24: =MONTH(AD24) -> 7 | AO24: =IF(C24="Yes",ROUNDUP(MONTH(AE24)/3,0),"") -> 4 | AP24: =IF(C24="Yes",MONTH(AE24),"") -> 11 | AQ24: =YEAR(AD24) -> 2013
A25: 297 | B25: 30 | C25: Yes | D25: Travel_Rarely | E25: Research & Development | F25: Bachelor | G25: Very High | H25: Female | I25: High | J25: Research Scientist | K25: Low | L25: Excellent | M25: Better | N25: Single | P25: Yes | Q25: 11 | R25: 5 | S25: 8 | T25: 0 | U25: 4 | V25: 3 | W25: 88 | X25: 1005 | Y25: 8556 | Z25: 2657 | AA25: 5 | AB25: 44773 | AC25: 33952 | AD25: 41350 | AE25: 43068 | AF25: 5 | AG25: 3_Between 30 and 40 | AH25: 1 | AI25: 25 | AJ25: 2 | AK25: 3_Between 3-5 years | AL25: Full-time | AM25: =ROUNDUP(MONTH(AD25)/3,0) -> 1 | AN25: =MONTH(AD25) -> 3 | AO25: =IF(C25="Yes",ROUNDUP(MONTH(AE25)/3,0),"") -> 4 | AP25: =IF(C25="Yes",MONTH(AE25),"") -> 11 | AQ25: =YEAR(AD25) -> 2013
A26: 1905 | B26: 34 | C26: Yes | D26: Non-Travel | E26: Research & Development | F26: Master | G26: Very High | H26: Male | I26: Low | J26: Research Scientist | K26: Low | L26: Outstanding | M26: Better | N26: Married | O26: Low | P26: Yes | Q26: 23 | R26: 1 | S26: 5 | T26: 3 | U26: 0 | V26: 16 | W26: 85 | X26: 967 | Y26: 14460 | Z26: 2307 | AA26: 2 | AB26: 44773 | AC26: 32420 | AD26: 41417 | AE26: 43083 | AF26: 5 | AG26: 3_Between 30 and 40 | AH26: 1 | AI26: 29 | AJ26: 2 | AK26: 3_Between 3-5 years | AL26: Full-time | AM26: =ROUNDUP(MONTH(AD26)/3,0) -> 2 | AN26: =MONTH(AD26) -> 5 | AO26: =IF(C26="Yes",ROUNDUP(MONTH(AE26)/3,0),"") -> 4 | AP26: =IF(C26="Yes",MONTH(AE26),"") -> 12 | AQ26: =YEAR(AD26) -> 2013
A27: 1489 | B27: 34 | C27: Yes | D27: Travel_Rarely | E27: Sales | F27: Master | G27: Low | H27: Female | I27: Medium | J27: Sales Executive | K27: Medium | L27: Outstanding | M27: Best | N27: Single | P27: Yes | Q27: 23 | R27: 0 | S27: 16 | T27: 10 | U27: 10 | V27: 24 | W27: 40 | X27: 790 | Y27: 7815 | Z27: 4599 | AA27: 2 | AB27: 44773 | AC27: 32384 | AD27: 37945 | AE27: 43098 | AF27: 14 | AG27: 3_Between 30 and 40 | AH27: 1 | AI27: 20 | AJ27: 1 | AK27: 5_Between 10-15 years | AL27: Full-time | AM27: =ROUNDUP(MONTH(AD27)/3,0) -> 4 | AN27: =MONTH(AD27) -> 11 | AO27: =IF(C27="Yes",ROUNDUP(MONTH(AE27)/3,0),"") -> 4 | AP27: =IF(C27="Yes",MONTH(AE27),"") -> 12 | AQ27: =YEAR(AD27) -> 2003
A28: 785 | B28: 47 | C28: Yes | D28: Travel_Frequently | E28: Sales | F28: College | G28: Medium | H28: Female | I28: Very High | J28: Sales Executive | K28: High | L28: Excellent | M28: Better | N28: Single | P28: Yes | Q28: 12 | R28: 4 | S28: 8 | T28: 1 | U28: 3 | V28: 27 | W28: 77 | X28: 719 | Y28: 10339 | Z28: 6397 | AA28: 2 | AB28: 44773 | AC28: 27941 | AD28: 41493 | AE28: 43122 | AF28: 4 | AG28: 4_Between 40 and 50 | AH28: 1 | AI28: 43 | AJ28: 1 | AK28: 3_Between 3-5 years | AL28: Contractor | AM28: =ROUNDUP(MONTH(AD28)/3,0) -> 3 | AN28: =MONTH(AD28) -> 8 | AO28: =IF(C28="Yes",ROUNDUP(MONTH(AE28)/3,0),"") -> 1 | AP28: =IF(C28="Yes",MONTH(AE28),"") -> 1 | AQ28: =YEAR(AD28) -> 2013
A29: 1389 | B29: 31 | C29: Yes | D29: Travel_Rarely | E29: Research & Development | F29: Master | G29: Very High | H29: Male | I29: High | J29: Manufacturing Director | K29: High | L29: Good | M29: Good | N29: Married | O29: Mid | P29: Yes | Q29: 15 | R29: 1 | S29: 10 | T29: 6 | U29: 7 | V29: 22 | W29: 98 | X29: 330 | Y29: 21057 | Z29: 6179 | AA29: 3 | AB29: 44773 | AC29: 33767 | AD29: 39510 | AE29: 43124 | AF29: 10 | AG29: 3_Between 30 and 40 | AH29: 1 | AI29: 21 | AJ29: 1 | AK29: 5_Between 10-15 years | AL29: Full-time | AM29: =ROUNDUP(MONTH(AD29)/3,0) -> 1 | AN29: =MONTH(AD29) -> 3 | AO29: =IF(C29="Yes",ROUNDUP(MONTH(AE29)/3,0),"") -> 1 | AP29: =IF(C29="Yes",MONTH(AE29),"") -> 1 | AQ29: =YEAR(AD29) -> 2008
A30: 1318 | B30: 40 | C30: Yes | D30: Travel_Rarely | E30: Sales | F30: Master | G30: Very High | H30: Male | I30: Medium | J30: Sales Executive | K30: Medium | L30: Good | M30: Better | N30: Single | P30: Yes | Q30: 12 | R30: 2 | S30: 9 | T30: 1 | U30: 0 | V30: 25 | W30: 57 | X30: 299 | Y30: 17235 | Z30: 9094 | AA30: 2 | AB30: 44773 | AC30: 30201 | AD30: 41485 | AE30: 43139 | AF30: 5 | AG30: 4_Between 40 and 50 | AH30: 2 | AI30: 35 | AJ30: 2 | AK30: 3_Between 3-5 years | AL30: Full-time | AM30: =ROUNDUP(MONTH(AD30)/3,0) -> 3 | AN30: =MONTH(AD30) -> 7 | AO30: =IF(C30="Yes",ROUNDUP(MONTH(AE30)/3,0),"") -> 1 | AP30: =IF(C30="Yes",MONTH(AE30),"") -> 2 | AQ30: =YEAR(AD30) -> 2013
A31: 1684 | B31: 23 | C31: Yes | D31: Travel_Rarely | E31: Research & Development | F31: Below College | G31: Very High | H31: Male | I31: Medium | J31: Laboratory Technician | K31: High | L31: Excellent | M31: Better | N31: Single | P31: Yes | Q31: 11 | R31: 1 | S31: 5 | T31: 1 | U31: 2 | V31: 8 | W31: 93 | X31: 1320 | Y31: 20586 | Z31: 3989 | AA31: 2 | AB31: 44773 | AC31: 36441 | AD31: 41614 | AE31: 43139 | AF31: 4 | AG31: 2_Between 20 and 30 | AH31: 2 | AI31: 19 | AJ31: 1 | AK31: 3_Between 3-5 years | AL31: Full-time | AM31: =ROUNDUP(MONTH(AD31)/3,0) -> 4 | AN31: =MONTH(AD31) -> 12 | AO31: =IF(C31="Yes",ROUNDUP(MONTH(AE31)/3,0),"") -> 1 | AP31: =IF(C31="Yes",MONTH(AE31),"") -> 2 | AQ31: =YEAR(AD31) -> 2013
A32: 1487 | B32: 29 | C32: Yes | D32: Travel_Frequently | E32: Sales | F32: Bachelor | G32: Low | H32: Female | I32: High | J32: Sales Executive | K32: Medium | L32: Excellent | M32: Bad | N32: Single | P32: No | Q32: 11 | R32: 5 | S32: 7 | T32: 0 | U32: 0 | V32: 13 | W32: 51 | X32: 115 | Y32: 17485 | Z32: 5765 | AA32: 4 | AB32: 44773 | AC32: 34456 | AD32: 41430 | AE32: 43139 | AF32: 5 | AG32: 2_Between 20 and 30 | AH32: 1 | AI32: 24 | AJ32: 1 | AK32: 3_Between 3-5 years | AL32: Full-time | AM32: =ROUNDUP(MONTH(AD32)/3,0) -> 2 | AN32: =MONTH(AD32) -> 6 | AO32: =IF(C32="Yes",ROUNDUP(MONTH(AE32)/3,0),"") -> 1 | AP32: =IF(C32="Yes",MONTH(AE32),"") -> 2 | AQ32: =YEAR(AD32) -> 2013
A33: 27 | B33: 36 | C33: Yes | D33: Travel_Rarely | E33: Sales | F33: Master | G33: High | H33: Male | I33: Medium | J33: Sales Representative | K33: Low | L33: Outstanding | M33: Better | N33: Single | P33: No | Q33: 23 | R33: 7 | S33: 10 | T33: 0 | U33: 3 | V33: 9 | W33: 82 | X33: 1218 | Y33: 6986 | Z33: 3407 | AA33: 4 | AB33: 44773 | AC33: 31780 | AD33: 41506 | AE33: 43150 | AF33: 5 | AG33: 3_Between 30 and 40 | AH33: 1 | AI33: 31 | AJ33: 1 | AK33: 3_Between 3-5 years | AL33: Full-time | AM33: =ROUNDUP(MONTH(AD33)/3,0) -> 3 | AN33: =MONTH(AD33) -> 8 | AO33: =IF(C33="Yes",ROUNDUP(MONTH(AE33)/3,0),"") -> 1 | AP33: =IF(C33="Yes",MONTH(AE33),"") -> 2 | AQ33: =YEAR(AD33) -> 2013
A34: 1818 | B34: 26 | C34: Yes | D34: Travel_Rarely | E34: Human Resources | F34: College | G34: Very High | H34: Female | I34: High | J34: Human Resources | K34: Medium | L34: Low | M34: Better | N34: Married | P34: Yes | Q34: 11 | R34: 0 | S34: 6 | T34: 1 | U34: 4 | V34: 20 | W34: 69 | X34: 920 | Y34: 6889 | Z34: 2148 | AA34: 3 | AB34: 44773 | AC34: 35635 | AD34: 41649 | AE34: 43190 | AF34: 4 | AG34: 2_Between 20 and 30 | AH34: 2 | AI34: 22 | AJ34: 1 | AK34: 3_Between 3-5 years | AL34: Full-time | AM34: =ROUNDUP(MONTH(AD34)/3,0) -> 1 | AN34: =MONTH(AD34) -> 1 | AO34: =IF(C34="Yes",ROUNDUP(MONTH(AE34)/3,0),"") -> 1 | AP34: =IF(C34="Yes",MONTH(AE34),"") -> 3 | AQ34: =YEAR(AD34) -> 2014
A35: 1809 | B35: 37 | C35: Yes | D35: Travel_Rarely | E35: Research & Development | F35: Master | G35: Very High | H35: Male | I35: High | J35: Manufacturing Director | K35: Low | L35: Excellent | M35: Bad | N35: Single | P35: No | Q35: 15 | R35: 1 | S35: 10 | T35: 0 | U35: 8 | V35: 10 | W35: 58 | X35: 370 | Y35: 4992 | Z35: 4213 | AA35: 4 | AB35: 44773 | AC35: 31479 | AD35: 39598 | AE35: 43190 | AF35: 10 | AG35: 3_Between 30 and 40 | AH35: 1 | AI35: 27 | AJ35: 1 | AK35: 5_Between 10-15 years | AL35: Full-time | AM35: =ROUNDUP(MONTH(AD35)/3,0) -> 2 | AN35: =MONTH(AD35) -> 5 | AO35: =IF(C35="Yes",ROUNDUP(MONTH(AE35)/3,0),"") -> 1 | AP35: =IF(C35="Yes",MONTH(AE35),"") -> 3 | AQ35: =YEAR(AD35) -> 2008
A36: 1792 | B36: 44 | C36: Yes | D36: Travel_Frequently | E36: Research & Development | F36: College | G36: High | H36: Male | I36: High | J36: Research Scientist | K36: Medium | L36: Excellent | M36: Good | N36: Divorced | O36: High | P36: Yes | Q36: 12 | R36: 1 | S36: 6 | T36: 2 | U36: 3 | V36: 1 | W36: 99 | X36: 429 | Y36: 11092 | Z36: 2342 | AA36: 2 | AB36: 44773 | AC36: 28869 | AD36: 41664 | AE36: 43201 | AF36: 4 | AG36: 4_Between 40 and 50 | AH36: 1 | AI36: 40 | AJ36: 1 | AK36: 3_Between 3-5 years | AL36: Full-time | AM36: =ROUNDUP(MONTH(AD36)/3,0) -> 1 | AN36: =MONTH(AD36) -> 1 | AO36: =IF(C36="Yes",ROUNDUP(MONTH(AE36)/3,0),"") -> 2 | AP36: =IF(C36="Yes",MONTH(AE36),"") -> 4 | AQ36: =YEAR(AD36) -> 2014
A37: 433 | B37: 52 | C37: Yes | D37: Travel_Rarely | E37: Research & Development | F37: Master | G37: High | H37: Male | I37: Medium | J37: Research Scientist | K37: Medium | L37: Excellent | M37: Good | N37: Married | P37: No | Q37: 15 | R37: 2 | S37: 11 | T37: 7 | U37: 7 | V37: 8 | W37: 85 | X37: 723 | Y37: 17747 | Z37: 4941 | AA37: 3 | AB37: 44773 | AC37: 26011 | AD37: 40331 | AE37: 43211 | AF37: 8 | AG37: 5_Between 50 and 60 | AH37: 1 | AI37: 44 | AJ37: 1 | AK37: 4_Between 5-10 years | AL37: Contractor | AM37: =ROUNDUP(MONTH(AD37)/3,0) -> 2 | AN37: =MONTH(AD37) -> 6 | AO37: =IF(C37="Yes",ROUNDUP(MONTH(AE37)/3,0),"") -> 2 | AP37: =IF(C37="Yes",MONTH(AE37),"") -> 4 | AQ37: =YEAR(AD37) -> 2010
A38: 842 | B38: 55 | C38: Yes | D38: Travel_Rarely | E38: Sales | F38: Below College | G38: High | H38: Male | I38: High | J38: Sales Executive | K38: Very High | L38: Excellent | M38: Good | N38: Single | P38: No | Q38: 16 | R38: 4 | S38: 12 | T38: 7 | U38: 3 | V38: 2 | W38: 37 | X38: 436 | Y38: 21519 | Z38: 5160 | AA38: 3 | AB38: 44773 | AC38: 24951 | AD38: 40282 | AE38: 43232 | AF38: 8 | AG38: 5_Between 50 and 60 | AH38: 1 | AI38: 47 | AJ38: 1 | AK38: 4_Between 5-10 years | AL38: Contractor | AM38: =ROUNDUP(MONTH(AD38)/3,0) -> 2 | AN38: =MONTH(AD38) -> 4 | AO38: =IF(C38="Yes",ROUNDUP(MONTH(AE38)/3,0),"") -> 2 | AP38: =IF(C38="Yes",MONTH(AE38),"") -> 5 | AQ38: =YEAR(AD38) -> 2010
A39: 1534 | B39: 40 | C39: Yes | D39: Travel_Rarely | E39: Research & Development | F39: Master | G39: Very High | H39: Male | I39: High | J39: Laboratory Technician | K39: Low | L39: Excellent | M39: Bad | N39: Single | P39: No | Q39: 14 | R39: 3 | S39: 15 | T39: 1 | U39: 0 | V39: 9 | W39: 86 | X39: 676 | Y39: 21831 | Z39: 2018 | AA39: 3 | AB39: 44773 | AC39: 30226 | AD39: 41636 | AE39: 43233 | AF39: 4 | AG39: 4_Between 40 and 50 | AH39: 2 | AI39: 36 | AJ39: 1 | AK39: 3_Between 3-5 years | AL39: Full-time | AM39: =ROUNDUP(MONTH(AD39)/3,0) -> 4 | AN39: =MONTH(AD39) -> 12 | AO39: =IF(C39="Yes",ROUNDUP(MONTH(AE39)/3,0),"") -> 2 | AP39: =IF(C39="Yes",MONTH(AE39),"") -> 5 | AQ39: =YEAR(AD39) -> 2013
A40: 787 | B40: 55 | C40: Yes | D40: Travel_Rarely | E40: Research & Development | F40: Bachelor | G40: Very High | H40: Male | I40: High | J40: Manager | K40: Low | L40: Excellent | M40: Better | N40: Married | O40: Low | P40: Yes | Q40: 13 | R40: 5 | S40: 24 | T40: 1 | U40: 4 | V40: 2 | W40: 78 | X40: 725 | Y40: 21199 | Z40: 19859 | AA40: 2 | AB40: 44773 | AC40: 24886 | AD40: 41451 | AE40: 43257 | AF40: 5 | AG40: 5_Between 50 and 60 | AH40: 1 | AI40: 50 | AJ40: 1 | AK40: 3_Between 3-5 years | AL40: Full-time | AM40: =ROUNDUP(MONTH(AD40)/3,0) -> 2 | AN40: =MONTH(AD40) -> 6 | AO40: =IF(C40="Yes",ROUNDUP(MONTH(AE40)/3,0),"") -> 2 | AP40: =IF(C40="Yes",MONTH(AE40),"") -> 6 | AQ40: =YEAR(AD40) -> 2013
...

Sheet Notes
A1: About this workbook
A2: Every number is a live formula on the Data sheet. Use the four orange filters on the Interactive Dashboard (Department, Employment, Gender, Hire year) and the whole report recalculates.
A4: Corrections made to the original dashboard
A5: 1. Termination rate now uses the brief's formula, Termination / Headcount (133 / 828 = 16.1% for R&D). The original card showed 25%.
A6: 2. Terminations by quarter and month now use DateDeparture (when people left). The original charts used DateStart (when they joined).
A7: 3. Education and job-satisfaction commentary now matches the selected department. The original text quoted whole-company figures.
A8: 4. 'Monthly Salary trends' is renamed 'Salary by Hire Month', because the data holds annual salary by hire date, not monthly payroll.
A9: 5. Quarterly new hires now count everyone hired in each quarter, including people who later left.
A11: Data notes
A12: Source: HR employee dataset supplied with the training brief 'HR Analytics Report' (1,470 employees, 3 departments). Data snapshot date: 31-Jul-2022 (DateToday column).
A13: Helper columns AM:AP on the Data sheet derive hire/leave quarter and month from the date columns.
A14: The Age and YearsAtCompany columns do not always match DateBirth/DateStart; figures here use the stored columns as given.
